Workbook

Sheet Raw Data
A1: HUL — Raw Financial Data (Rs Crore, Consolidated)
A2: Source: Revenue figures verified vs. HUL consolidated annual results (FY21-FY25, Moneycontrol/TradingView coverage). COGS/Inventory/Receivables/Payables are compiled estimates from public aggregators (Screener, Tijori, TradingEconomics), anchored to verified FY24/FY25 balance sheet data points. Verify against HUL Annual Report for audit-grade precision.
A4: Year | B4: Revenue | C4: COGS | D4: Inventory | E4: Receivables | F4: Payables
A5: 2021 | B5: 47028 | C5: 22800 | D5: 2930 | E5: 1890 | F5: 7810
A6: 2022 | B6: 52446 | C6: 26800 | D6: 3360 | E6: 2200 | F6: 8760
A7: 2023 | B7: 60580 | C7: 30900 | D7: 3640 | E7: 2470 | F7: 9580
A8: 2024 | B8: 61896 | C8: 29900 | D8: 3812 | E8: 2690 | F8: 10148
A9: 2025 | B9: 63121 | C9: 30500 | D9: 3950 | E9: 2820 | F9: 11315

Sheet WC Calculations
A1: HUL — Working Capital Cycle (Days)
A2: All figures pull live from 'Raw Data'. Black = formulas.
A4: Year | B4: DIO | C4: DSO | D4: DPO | E4: CCC
A5: ='Raw Data'!A5 -> 2021 | B5: ='Raw Data'!D5/'Raw Data'!C5*365 -> 46.9 | C5: ='Raw Data'!E5/'Raw Data'!B5*365 -> 14.7 | D5: ='Raw Data'!F5/'Raw Data'!C5*365 -> 125.0 | E5: =B5+C5-D5 -> (63.5)
A6: ='Raw Data'!A6 -> 2022 | B6: ='Raw Data'!D6/'Raw Data'!C6*365 -> 45.8 | C6: ='Raw Data'!E6/'Raw Data'!B6*365 -> 15.3 | D6: ='Raw Data'!F6/'Raw Data'!C6*365 -> 119.3 | E6: =B6+C6-D6 -> (58.2)
A7: ='Raw Data'!A7 -> 2023 | B7: ='Raw Data'!D7/'Raw Data'!C7*365 -> 43.0 | C7: ='Raw Data'!E7/'Raw Data'!B7*365 -> 14.9 | D7: ='Raw Data'!F7/'Raw Data'!C7*365 -> 113.2 | E7: =B7+C7-D7 -> (55.3)
A8: ='Raw Data'!A8 -> 2024 | B8: ='Raw Data'!D8/'Raw Data'!C8*365 -> 46.5 | C8: ='Raw Data'!E8/'Raw Data'!B8*365 -> 15.9 | D8: ='Raw Data'!F8/'Raw Data'!C8*365 -> 123.9 | E8: =B8+C8-D8 -> (61.5)
A9: ='Raw Data'!A9 -> 2025 | B9: ='Raw Data'!D9/'Raw Data'!C9*365 -> 47.3 | C9: ='Raw Data'!E9/'Raw Data'!B9*365 -> 16.3 | D9: ='Raw Data'!F9/'Raw Data'!C9*365 -> 135.4 | E9: =B9+C9-D9 -> (71.8)

Sheet Forecast
A1: HUL — 3-Year Forecast (FY2026E-FY2028E)
A2: Assumptions in blue (editable). Revenue grown at CAGR FY21-25; DIO/DSO/DPO held at 3-yr average from WC Calculations.
A4: Assumptions
A5: Revenue CAGR (FY21-FY25) | B5: =('Raw Data'!B9/'Raw Data'!B5)^(1/4)-1 -> 7.6%
A6: Avg DIO (FY23-FY25) | B6: =AVERAGE('WC Calculations'!B7:B9) -> 45.6
A7: Avg DSO (FY23-FY25) | B7: =AVERAGE('WC Calculations'!C7:C9) -> 15.7
A8: Avg DPO (FY23-FY25) | B8: =AVERAGE('WC Calculations'!D7:D9) -> 124.2
A11: Year | B11: Revenue | C11: DIO | D11: DSO | E11: DPO
A12: 2026 | B12: ='Raw Data'!B9*(1+$B$5) -> 67,940 | C12: =$B$6 -> 45.6 | D12: =$B$7 -> 15.7 | E12: =$B$8 -> 124.2
A13: 2027 | B13: =B12*(1+$B$5) -> 73,128 | C13: =$B$6 -> 45.6 | D13: =$B$7 -> 15.7 | E13: =$B$8 -> 124.2
A14: 2028 | B14: =B13*(1+$B$5) -> 78,711 | C14: =$B$6 -> 45.6 | D14: =$B$7 -> 15.7 | E14: =$B$8 -> 124.2

Sheet Digital Twin Simulator
A1: HUL — Working Capital Digital Twin Simulator
A2: Edit 'New Scenario' values (blue) to instantly see impact on cash & CCC.
A4: Revenue & COGS basis (latest year, FY2025)
A5: Revenue (Rs Cr) | B5: ='Raw Data'!B9 -> 63,121
A6: COGS (Rs Cr) | B6: ='Raw Data'!C9 -> 30,500
A9: Variable | B9: Current | C9: New Scenario
A10: DIO | B10: 25 | C10: 22
A11: DSO | B11: 10 | C11: 8
A12: DPO | B12: 45 | C12: 48
A14: Output | B14: Value
A15: Current CCC (days) | B15: =B10+B11-B12 -> (10.0)
A16: New CCC (days) | B16: =C10+C11-C12 -> (18.0)
A17: CCC Improvement (days) | B17: =B15-B16 -> 8.0
A18: Cash Released — Inventory (Rs Cr) | B18: =(B10-C10)*$B$6/365 -> 251
A19: Cash Released — Receivables (Rs Cr) | B19: =(B11-C11)*$B$5/365 -> 346
A20: Cash Released — Payables (Rs Cr) | B20: =(C12-B12)*$B$6/365 -> 251
A21: Total Cash Released (Rs Cr) | B21: =SUM(B18:B20) -> 847
A22: Working Capital Improvement (% of Revenue) | B22: =B21/$B$5 -> 1.3%
A24: Business Scenario Analysis
A25: Compares Best/Base/Worst case working capital assumptions against FY2025 Revenue & COGS basis above (B5:B6).
A27: Scenario | B27: DIO | C27: DSO | D27: DPO | E27: CCC | F27: Cash Released (Rs Cr) | G27: Working Capital Impact
A28: Best Case | B28: 22 | C28: 8 | D28: 48 | E28: =B28+C28-D28 -> (18.0) | F28: =(($B$10-B28)*$B$6/365)+(($B$11-C28)*$B$5/365)+((D28-$B$12)*$B$6/365) -> 847 | G28: =F28/$B$5 -> 1.34%
A29: Base Case | B29: 25 | C29: 10 | D29: 45 | E29: =B29+C29-D29 -> (10.0) | F29: =(($B$10-B29)*$B$6/365)+(($B$11-C29)*$B$5/365)+((D29-$B$12)*$B$6/365) -> - | G29: =F29/$B$5 -> 0.00%
A30: Worst Case | B30: 30 | C30: 15 | D30: 40 | E30: =B30+C30-D30 -> 5.0 | F30: =(($B$10-B30)*$B$6/365)+(($B$11-C30)*$B$5/365)+((D30-$B$12)*$B$6/365) -> (1,700) | G30: =F30/$B$5 -> -2.69%
A32: Cash Released and WC Impact are measured against the 'Current' scenario (B10:B12) at FY2025 Revenue/COGS scale (B5:B6).
A35: Risk Indicators — Early Warning System
A36: Flags evaluated against the Base Case scenario above. Status updates automatically if assumptions change.
A38: Metric | B38: Current Value | C38: Threshold | D38: Status
A39: DIO > 50 | B39: =B29 -> 25.0 | C39: 50 | D39: =IF(B39>C39,"High Risk","OK") -> OK
A40: DSO > 30 | B40: =C29 -> 10.0 | C40: 30 | D40: =IF(B40>C40,"Medium Risk","OK") -> OK
A41: CCC > 0 | B41: =E29 -> (10.0) | C41: 0 | D41: =IF(B41>C41,"Warning","OK") -> OK

Sheet AI Output
A1: HUL — AI/Python Predicted Working Capital Cycle
A2: This sheet shows future predictions generated by a real scikit-learn LinearRegression model (one per metric, trained on FY2021-FY2025 actuals vs. Year). See AI_Predictions_Model.ipynb for the full model build, fit diagnostics, and chart. CCC is calculated as: CCC = DIO + DSO - DPO
A4: Year | B4: Predicted DIO | C4: Predicted DSO | D4: Predicted DPO | E4: Predicted CCC
A5: 2026 | B5: 46.3 | C5: 16.6 | D5: 131 | E5: =B5+C5-D5 -> (68.1)
A6: 2027 | B6: 46.5 | C6: 16.9 | D6: 133.5 | E6: =B6+C6-D6 -> (70.1)
A7: 2028 | B7: 46.6 | C7: 17.3 | D7: 136 | E7: =B7+C7-D7 -> (72.1)
A9: AI Insights
A10: Insight 1 | B10: Inventory efficiency expected to improve.
A11: Insight 2 | B11: Receivable collection period expected to reduce.
A12: Insight 3 | B12: Cash Conversion Cycle expected to become more negative.
A13: Insight 4 | B13: Working capital management remains strong.
A15: Formula: CCC = DIO + DSO - DPO
A33: Table for Multi Row Card (Page 4 — AI Insight 1-4)
A34: AI Insight 1 | B34: AI Insight 2 | C34: AI Insight 3 | D34: AI Insight 4
A35: Inventory efficiency expected to improve. | B35: Receivable collection period expected to reduce. | C35: Cash Conversion Cycle expected to become more negative. | D35: Working capital management remains strong.

Sheet Dashboard Data
A1: HUL — Dashboard Data (Flat Tables for Power BI)
A2: Static values only — no formulas. Refresh by re-pasting from earlier sheets.
A4: Table 1: Financials & Ratios by Year
A5: Year | B5: Revenue | C5: COGS | D5: Inventory | E5: Receivables | F5: Payables | G5: DIO | H5: DSO | I5: DPO | J5: CCC
A6: 2021 | B6: 47028 | C6: 22800 | D6: 2930 | E6: 1890 | F6: 7810 | G6: 46.9 | H6: 14.7 | I6: 125 | J6: -63.5
A7: 2022 | B7: 52446 | C7: 26800 | D7: 3360 | E7: 2200 | F7: 8760 | G7: 45.8 | H7: 15.3 | I7: 119.3 | J7: -58.2
A8: 2023 | B8: 60580 | C8: 30900 | D8: 3640 | E8: 2470 | F8: 9580 | G8: 43 | H8: 14.9 | I8: 113.2 | J8: -55.3
A9: 2024 | B9: 61896 | C9: 29900 | D9: 3812 | E9: 2690 | F9: 10148 | G9: 46.5 | H9: 15.9 | I9: 123.9 | J9: -61.5
A10: 2025 | B10: 63121 | C10: 30500 | D10: 3950 | E10: 2820 | F10: 11315 | G10: 47.3 | H10: 16.3 | I10: 135.4 | J10: -71.8
A13: Table 2: Forecast (FY2026E-FY2028E)
A14: Year | B14: Revenue | C14: DIO | D14: DSO | E14: DPO
A15: 2026 | B15: 67940 | C15: 45.6 | D15: 15.7 | E15: 124.2
A16: 2027 | B16: 73128 | C16: 45.6 | D16: 15.7 | E16: 124.2
A17: 2028 | B17: 78711 | C17: 45.6 | D17: 15.7 | E17: 124.2
A20: Table 3: Digital Twin Scenario
A21: Variable | B21: Current | C21: New Scenario
A22: DIO | B22: 25 | C22: 22
A23: DSO | B23: 10 | C23: 8
A24: DPO | B24: 45 | C24: 48
A26: Table 4: Simulator Outputs
A27: Output | B27: Value
A28: Current CCC (days) | B28: -10
A29: New CCC (days) | B29: -18
A30: Total Cash Released (Rs Cr) | B30: 847
A31: Working Capital Improvement (% of Revenue) | B31: 0.0134
A34: Table 5: Executive KPI Cards (FY2025 snapshot — use for Page 1 Cards)
A35: Revenue | B35: CCC | C35: Total Cash Released | D35: Working Capital Improvement %
A36: 63121 | B36: -71.8 | C36: 847 | D36: 0.0134
A39: Table 6: Cash Impact Breakdown (Page 3 — Cash Impact Breakdown chart)
A40: Impact Type | B40: Cash Released
A41: Inventory Impact | B41: 251
A42: Receivable Impact | B42: 346
A43: Payable Impact | B43: 251
A46: Table 7: Current vs Scenario Comparison (Page 3 comparison chart)
A47: Current DIO | B47: Scenario DIO | C47: Current DSO | D47: Scenario DSO | E47: Current DPO | F47: Scenario DPO
A48: 25 | B48: 22 | C48: 10 | D48: 8 | E48: 45 | F48: 48
A51: Table 8: Simulator KPI Cards (Page 3 — Card 1-4)
A52: Current CCC | B52: New CCC | C52: CCC Improvement | D52: Total Cash Released
A53: -10 | B53: -18 | C53: 8 | D53: 847
A56: Table 9: Business Scenario Analysis (Best / Base / Worst Case)
...
